<?xml version="1.0" encoding="UTF-8"?>
<testsuite name="unittest.loader._FailedTest-20240308095728" tests="1" file="unittest/loader.py" time="0.010" timestamp="2024-03-08T09:57:29" failures="0" errors="1" skipped="0">
	<testcase classname="unittest.loader._FailedTest" name="Assignment_tests" time="0.010" timestamp="2024-03-08T09:57:29">
		<error type="ImportError" message="Failed to import test module: Assignment_tests
Traceback (most recent call last):
  File &quot;/usr/lib/python3.10/unittest/loader.py&quot;, line 154, in loadTestsFromName
    module = __import__(module_name)
  File &quot;/home/kvenkatt/pyb/src/unittest/python/Assignment_tests.py&quot;, line 4, in &lt;module&gt;
    from group6 import group6
ModuleNotFoundError: No module named 'group6'
"><![CDATA[Traceback (most recent call last):
  File "/usr/lib/python3.10/unittest/case.py", line 59, in testPartExecutor
    yield
  File "/usr/lib/python3.10/unittest/case.py", line 591, in run
    self._callTestMethod(testMethod)
  File "/usr/lib/python3.10/unittest/case.py", line 549, in _callTestMethod
    method()
  File "/usr/lib/python3.10/unittest/loader.py", line 34, in testFailure
    raise self._exception
ImportError: Failed to import test module: Assignment_tests
Traceback (most recent call last):
  File "/usr/lib/python3.10/unittest/loader.py", line 154, in loadTestsFromName
    module = __import__(module_name)
  File "/home/kvenkatt/pyb/src/unittest/python/Assignment_tests.py", line 4, in <module>
    from group6 import group6
ModuleNotFoundError: No module named 'group6'

]]></error>
	</testcase>
</testsuite>
